Workbook

Sheet Student Calendar
A1: Monday | B1: Tuesday | C1: Wednesday | D1: Thursday | E1: Friday
A2: ='Teacher Calendar'!D2 -> 46265 | B2: ='Teacher Calendar'!E2 -> 46266 | C2: ='Teacher Calendar'!F2 -> 46267 | D2: ='Teacher Calendar'!G2 -> 46268 | E2: ='Teacher Calendar'!H2 -> 46269
A3: ='Teacher Calendar'!D3 -> 0.1 Get Acquainted | B3: ='Teacher Calendar'!E3 -> 0.1 Get Acquainted | C3: ='Teacher Calendar'!F3 -> 0.1 Get Acquainted | D3: ='Teacher Calendar'!G3 -> House Keeping | E3: ='Teacher Calendar'!H3
A4: ='Teacher Calendar'!D4 -> Warm Up | B4: ='Teacher Calendar'!E4 -> Warm Up | C4: ='Teacher Calendar'!F4 -> Warm Up | D4: ='Teacher Calendar'!G4 -> Warm Up | E4: ='Teacher Calendar'!H4 -> Labor Day
A5: ='Teacher Calendar'!D5 -> Notes | B5: ='Teacher Calendar'!E5 -> Investigation | C5: ='Teacher Calendar'!F5 -> Investigation | D5: ='Teacher Calendar'!G5 -> Activity | E5: ='Teacher Calendar'!H5
A6: ='Teacher Calendar'!D6 -> Practice Set | B6: ='Teacher Calendar'!E6 -> Practice Set | C6: ='Teacher Calendar'!F6 -> Activity | D6: ='Teacher Calendar'!G6 -> Return Portfolio | E6: ='Teacher Calendar'!H6
A7: ='Teacher Calendar'!D7 | B7: ='Teacher Calendar'!E7 -> Extra Practice | C7: ='Teacher Calendar'!F7 -> Practice Set | D7: ='Teacher Calendar'!G7 -> Overview | E7: ='Teacher Calendar'!H7
A8: ='Teacher Calendar'!D8 | B8: ='Teacher Calendar'!E8 | C8: ='Teacher Calendar'!F8 -> Extra Practice | D8: ='Teacher Calendar'!G8 -> Survey | E8: ='Teacher Calendar'!H8
A9: ='Teacher Calendar'!D9 | B9: ='Teacher Calendar'!E9 | C9: ='Teacher Calendar'!F9 | D9: ='Teacher Calendar'!G9 | E9: ='Teacher Calendar'!H9
A11: ='Teacher Calendar'!D15 -> 46265 | B11: ='Teacher Calendar'!E15 -> 46266 | C11: ='Teacher Calendar'!F15 -> 46267 | D11: ='Teacher Calendar'!G15 -> 46268 | E11: ='Teacher Calendar'!H15 -> 46269
A12: {=IFERROR(INDEX('Teacher Calendar'!$D$16:$D$25,SMALL(IF(('Teacher Calendar'!$D$16:$D$25<>"")*('Teacher Calendar'!$D$16:$D$25<>0),ROW('Teacher Calendar'!$D$16:$D$25)-ROW('Teacher Calendar'!$D$16)+1),1)),"")} -> 0.1 Get Acquainted | B12: {=IFERROR(INDEX('Teacher Calendar'!$E$16:$E$25,SMALL(IF(('Teacher Calendar'!$E$16:$E$25<>"")*('Teacher Calendar'!$E$16:$E$25<>0),ROW('Teacher Calendar'!$E$16:$E$25)-ROW('Teacher Calendar'!$E$16)+1),1)),"")} -> 0.1 Get Acquainted | C12: {=IFERROR(INDEX('Teacher Calendar'!$F$16:$F$25,SMALL(IF(('Teacher Calendar'!$F$16:$F$25<>"")*('Teacher Calendar'!$F$16:$F$25<>0),ROW('Teacher Calendar'!$F$16:$F$25)-ROW('Teacher Calendar'!$F$16)+1),1)),"")} -> 0.1 Get Acquainted | D12: {=IFERROR(INDEX('Teacher Calendar'!$G$16:$G$25,SMALL(IF(('Teacher Calendar'!$G$16:$G$25<>"")*('Teacher Calendar'!$G$16:$G$25<>0),ROW('Teacher Calendar'!$G$16:$G$25)-ROW('Teacher Calendar'!$G$16)+1),1)),"")} -> House Keeping | E12: {=IFERROR(INDEX('Teacher Calendar'!$H$16:$H$25,SMALL(IF(('Teacher Calendar'!$H$16:$H$25<>"")*('Teacher Calendar'!$H$16:$H$25<>0),ROW('Teacher Calendar'!$H$16:$H$25)-ROW('Teacher Calendar'!$H$16)+1),1)),"")} -> Labor Day
A13: {=IFERROR(INDEX('Teacher Calendar'!$D$16:$D$25,SMALL(IF(('Teacher Calendar'!$D$16:$D$25<>"")*('Teacher Calendar'!$D$16:$D$25<>0),ROW('Teacher Calendar'!$D$16:$D$25)-ROW('Teacher Calendar'!$D$16)+1),2)),"")} -> Warm Up | B13: {=IFERROR(INDEX('Teacher Calendar'!$E$16:$E$25,SMALL(IF(('Teacher Calendar'!$E$16:$E$25<>"")*('Teacher Calendar'!$E$16:$E$25<>0),ROW('Teacher Calendar'!$E$16:$E$25)-ROW('Teacher Calendar'!$E$16)+1),2)),"")} -> Warm Up | C13: {=IFERROR(INDEX('Teacher Calendar'!$F$16:$F$25,SMALL(IF(('Teacher Calendar'!$F$16:$F$25<>"")*('Teacher Calendar'!$F$16:$F$25<>0),ROW('Teacher Calendar'!$F$16:$F$25)-ROW('Teacher Calendar'!$F$16)+1),2)),"")} -> Warm Up | D13: {=IFERROR(INDEX('Teacher Calendar'!$G$16:$G$25,SMALL(IF(('Teacher Calendar'!$G$16:$G$25<>"")*('Teacher Calendar'!$G$16:$G$25<>0),ROW('Teacher Calendar'!$G$16:$G$25)-ROW('Teacher Calendar'!$G$16)+1),2)),"")} -> Warm Up | E13: {=IFERROR(INDEX('Teacher Calendar'!$H$16:$H$25,SMALL(IF(('Teacher Calendar'!$H$16:$H$25<>"")*('Teacher Calendar'!$H$16:$H$25<>0),ROW('Teacher Calendar'!$H$16:$H$25)-ROW('Teacher Calendar'!$H$16)+1),2)),"")}
A14: {=IFERROR(INDEX('Teacher Calendar'!$D$16:$D$25,SMALL(IF(('Teacher Calendar'!$D$16:$D$25<>"")*('Teacher Calendar'!$D$16:$D$25<>0),ROW('Teacher Calendar'!$D$16:$D$25)-ROW('Teacher Calendar'!$D$16)+1),3)),"")} -> Notes | B14: {=IFERROR(INDEX('Teacher Calendar'!$E$16:$E$25,SMALL(IF(('Teacher Calendar'!$E$16:$E$25<>"")*('Teacher Calendar'!$E$16:$E$25<>0),ROW('Teacher Calendar'!$E$16:$E$25)-ROW('Teacher Calendar'!$E$16)+1),3)),"")} -> Investigation | C14: {=IFERROR(INDEX('Teacher Calendar'!$F$16:$F$25,SMALL(IF(('Teacher Calendar'!$F$16:$F$25<>"")*('Teacher Calendar'!$F$16:$F$25<>0),ROW('Teacher Calendar'!$F$16:$F$25)-ROW('Teacher Calendar'!$F$16)+1),3)),"")} -> Investigation | D14: {=IFERROR(INDEX('Teacher Calendar'!$G$16:$G$25,SMALL(IF(('Teacher Calendar'!$G$16:$G$25<>"")*('Teacher Calendar'!$G$16:$G$25<>0),ROW('Teacher Calendar'!$G$16:$G$25)-ROW('Teacher Calendar'!$G$16)+1),3)),"")} -> Activity | E14: {=IFERROR(INDEX('Teacher Calendar'!$H$16:$H$25,SMALL(IF(('Teacher Calendar'!$H$16:$H$25<>"")*('Teacher Calendar'!$H$16:$H$25<>0),ROW('Teacher Calendar'!$H$16:$H$25)-ROW('Teacher Calendar'!$H$16)+1),3)),"")}
A15: {=IFERROR(INDEX('Teacher Calendar'!$D$16:$D$25,SMALL(IF(('Teacher Calendar'!$D$16:$D$25<>"")*('Teacher Calendar'!$D$16:$D$25<>0),ROW('Teacher Calendar'!$D$16:$D$25)-ROW('Teacher Calendar'!$D$16)+1),4)),"")} -> Practice Set | B15: {=IFERROR(INDEX('Teacher Calendar'!$E$16:$E$25,SMALL(IF(('Teacher Calendar'!$E$16:$E$25<>"")*('Teacher Calendar'!$E$16:$E$25<>0),ROW('Teacher Calendar'!$E$16:$E$25)-ROW('Teacher Calendar'!$E$16)+1),4)),"")} -> Practice Set | C15: {=IFERROR(INDEX('Teacher Calendar'!$F$16:$F$25,SMALL(IF(('Teacher Calendar'!$F$16:$F$25<>"")*('Teacher Calendar'!$F$16:$F$25<>0),ROW('Teacher Calendar'!$F$16:$F$25)-ROW('Teacher Calendar'!$F$16)+1),4)),"")} -> Activity | D15: {=IFERROR(INDEX('Teacher Calendar'!$G$16:$G$25,SMALL(IF(('Teacher Calendar'!$G$16:$G$25<>"")*('Teacher Calendar'!$G$16:$G$25<>0),ROW('Teacher Calendar'!$G$16:$G$25)-ROW('Teacher Calendar'!$G$16)+1),4)),"")} -> Return Portfolio | E15: {=IFERROR(INDEX('Teacher Calendar'!$H$16:$H$25,SMALL(IF(('Teacher Calendar'!$H$16:$H$25<>"")*('Teacher Calendar'!$H$16:$H$25<>0),ROW('Teacher Calendar'!$H$16:$H$25)-ROW('Teacher Calendar'!$H$16)+1),4)),"")}
A16: {=IFERROR(INDEX('Teacher Calendar'!$D$16:$D$25,SMALL(IF(('Teacher Calendar'!$D$16:$D$25<>"")*('Teacher Calendar'!$D$16:$D$25<>0),ROW('Teacher Calendar'!$D$16:$D$25)-ROW('Teacher Calendar'!$D$16)+1),5)),"")} | B16: {=IFERROR(INDEX('Teacher Calendar'!$E$16:$E$25,SMALL(IF(('Teacher Calendar'!$E$16:$E$25<>"")*('Teacher Calendar'!$E$16:$E$25<>0),ROW('Teacher Calendar'!$E$16:$E$25)-ROW('Teacher Calendar'!$E$16)+1),5)),"")} -> Extra Practice | C16: {=IFERROR(INDEX('Teacher Calendar'!$F$16:$F$25,SMALL(IF(('Teacher Calendar'!$F$16:$F$25<>"")*('Teacher Calendar'!$F$16:$F$25<>0),ROW('Teacher Calendar'!$F$16:$F$25)-ROW('Teacher Calendar'!$F$16)+1),5)),"")} -> Practice Set | D16: {=IFERROR(INDEX('Teacher Calendar'!$G$16:$G$25,SMALL(IF(('Teacher Calendar'!$G$16:$G$25<>"")*('Teacher Calendar'!$G$16:$G$25<>0),ROW('Teacher Calendar'!$G$16:$G$25)-ROW('Teacher Calendar'!$G$16)+1),5)),"")} -> Overview | E16: {=IFERROR(INDEX('Teacher Calendar'!$H$16:$H$25,SMALL(IF(('Teacher Calendar'!$H$16:$H$25<>"")*('Teacher Calendar'!$H$16:$H$25<>0),ROW('Teacher Calendar'!$H$16:$H$25)-ROW('Teacher Calendar'!$H$16)+1),5)),"")}
A17: {=IFERROR(INDEX('Teacher Calendar'!$D$16:$D$25,SMALL(IF(('Teacher Calendar'!$D$16:$D$25<>"")*('Teacher Calendar'!$D$16:$D$25<>0),ROW('Teacher Calendar'!$D$16:$D$25)-ROW('Teacher Calendar'!$D$16)+1),6)),"")} | B17: {=IFERROR(INDEX('Teacher Calendar'!$E$16:$E$25,SMALL(IF(('Teacher Calendar'!$E$16:$E$25<>"")*('Teacher Calendar'!$E$16:$E$25<>0),ROW('Teacher Calendar'!$E$16:$E$25)-ROW('Teacher Calendar'!$E$16)+1),6)),"")} | C17: {=IFERROR(INDEX('Teacher Calendar'!$F$16:$F$25,SMALL(IF(('Teacher Calendar'!$F$16:$F$25<>"")*('Teacher Calendar'!$F$16:$F$25<>0),ROW('Teacher Calendar'!$F$16:$F$25)-ROW('Teacher Calendar'!$F$16)+1),6)),"")} -> Extra Practice | D17: {=IFERROR(INDEX('Teacher Calendar'!$G$16:$G$25,SMALL(IF(('Teacher Calendar'!$G$16:$G$25<>"")*('Teacher Calendar'!$G$16:$G$25<>0),ROW('Teacher Calendar'!$G$16:$G$25)-ROW('Teacher Calendar'!$G$16)+1),6)),"")} -> Survey | E17: {=IFERROR(INDEX('Teacher Calendar'!$H$16:$H$25,SMALL(IF(('Teacher Calendar'!$H$16:$H$25<>"")*('Teacher Calendar'!$H$16:$H$25<>0),ROW('Teacher Calendar'!$H$16:$H$25)-ROW('Teacher Calendar'!$H$16)+1),6)),"")}
A18: {=IFERROR(INDEX('Teacher Calendar'!$D$16:$D$25,SMALL(IF(('Teacher Calendar'!$D$16:$D$25<>"")*('Teacher Calendar'!$D$16:$D$25<>0),ROW('Teacher Calendar'!$D$16:$D$25)-ROW('Teacher Calendar'!$D$16)+1),7)),"")} | B18: {=IFERROR(INDEX('Teacher Calendar'!$E$16:$E$25,SMALL(IF(('Teacher Calendar'!$E$16:$E$25<>"")*('Teacher Calendar'!$E$16:$E$25<>0),ROW('Teacher Calendar'!$E$16:$E$25)-ROW('Teacher Calendar'!$E$16)+1),7)),"")} | C18: {=IFERROR(INDEX('Teacher Calendar'!$F$16:$F$25,SMALL(IF(('Teacher Calendar'!$F$16:$F$25<>"")*('Teacher Calendar'!$F$16:$F$25<>0),ROW('Teacher Calendar'!$F$16:$F$25)-ROW('Teacher Calendar'!$F$16)+1),7)),"")} | D18: {=IFERROR(INDEX('Teacher Calendar'!$G$16:$G$25,SMALL(IF(('Teacher Calendar'!$G$16:$G$25<>"")*('Teacher Calendar'!$G$16:$G$25<>0),ROW('Teacher Calendar'!$G$16:$G$25)-ROW('Teacher Calendar'!$G$16)+1),7)),"")} | E18: {=IFERROR(INDEX('Teacher Calendar'!$H$16:$H$25,SMALL(IF(('Teacher Calendar'!$H$16:$H$25<>"")*('Teacher Calendar'!$H$16:$H$25<>0),ROW('Teacher Calendar'!$H$16:$H$25)-ROW('Teacher Calendar'!$H$16)+1),7)),"")}
A19: ='Teacher Calendar'!D42 -> 46272 | B19: ='Teacher Calendar'!E42 -> 46273 | C19: ='Teacher Calendar'!F42 -> 46274 | D19: ='Teacher Calendar'!G42 -> 46275 | E19: ='Teacher Calendar'!H42 -> 46276
A20: {=IFERROR(INDEX('Teacher Calendar'!$D$43:$D$52,SMALL(IF(('Teacher Calendar'!$D$43:$D$52<>"")*('Teacher Calendar'!$D$43:$D$52<>0),ROW('Teacher Calendar'!$D$43:$D$52)-ROW('Teacher Calendar'!$D$43)+1),1)),"")} | B20: {=IFERROR(INDEX('Teacher Calendar'!$E$43:$E$52,SMALL(IF(('Teacher Calendar'!$E$43:$E$52<>"")*('Teacher Calendar'!$E$43:$E$52<>0),ROW('Teacher Calendar'!$E$43:$E$52)-ROW('Teacher Calendar'!$E$43)+1),1)),"")} -> 1.1: Think Physics | C20: {=IFERROR(INDEX('Teacher Calendar'!$F$43:$F$52,SMALL(IF(('Teacher Calendar'!$F$43:$F$52<>"")*('Teacher Calendar'!$F$43:$F$52<>0),ROW('Teacher Calendar'!$F$43:$F$52)-ROW('Teacher Calendar'!$F$43)+1),1)),"")} -> 1.1: Think Physics | D20: {=IFERROR(INDEX('Teacher Calendar'!$G$43:$G$52,SMALL(IF(('Teacher Calendar'!$G$43:$G$52<>"")*('Teacher Calendar'!$G$43:$G$52<>0),ROW('Teacher Calendar'!$G$43:$G$52)-ROW('Teacher Calendar'!$G$43)+1),1)),"")} -> 1.1: Think Physics | E20: {=IFERROR(INDEX('Teacher Calendar'!$H$43:$H$52,SMALL(IF(('Teacher Calendar'!$H$43:$H$52<>"")*('Teacher Calendar'!$H$43:$H$52<>0),ROW('Teacher Calendar'!$H$43:$H$52)-ROW('Teacher Calendar'!$H$43)+1),1)),"")} -> 1.2: Forces & N1L
A21: {=IFERROR(INDEX('Teacher Calendar'!$D$43:$D$52,SMALL(IF(('Teacher Calendar'!$D$43:$D$52<>"")*('Teacher Calendar'!$D$43:$D$52<>0),ROW('Teacher Calendar'!$D$43:$D$52)-ROW('Teacher Calendar'!$D$43)+1),2)),"")} | B21: {=IFERROR(INDEX('Teacher Calendar'!$E$43:$E$52,SMALL(IF(('Teacher Calendar'!$E$43:$E$52<>"")*('Teacher Calendar'!$E$43:$E$52<>0),ROW('Teacher Calendar'!$E$43:$E$52)-ROW('Teacher Calendar'!$E$43)+1),2)),"")} -> Warm Up | C21: {=IFERROR(INDEX('Teacher Calendar'!$F$43:$F$52,SMALL(IF(('Teacher Calendar'!$F$43:$F$52<>"")*('Teacher Calendar'!$F$43:$F$52<>0),ROW('Teacher Calendar'!$F$43:$F$52)-ROW('Teacher Calendar'!$F$43)+1),2)),"")} -> Warm Up | D21: {=IFERROR(INDEX('Teacher Calendar'!$G$43:$G$52,SMALL(IF(('Teacher Calendar'!$G$43:$G$52<>"")*('Teacher Calendar'!$G$43:$G$52<>0),ROW('Teacher Calendar'!$G$43:$G$52)-ROW('Teacher Calendar'!$G$43)+1),2)),"")} -> Warm Up | E21: {=IFERROR(INDEX('Teacher Calendar'!$H$43:$H$52,SMALL(IF(('Teacher Calendar'!$H$43:$H$52<>"")*('Teacher Calendar'!$H$43:$H$52<>0),ROW('Teacher Calendar'!$H$43:$H$52)-ROW('Teacher Calendar'!$H$43)+1),2)),"")} -> Warm Up
A22: {=IFERROR(INDEX('Teacher Calendar'!$D$43:$D$52,SMALL(IF(('Teacher Calendar'!$D$43:$D$52<>"")*('Teacher Calendar'!$D$43:$D$52<>0),ROW('Teacher Calendar'!$D$43:$D$52)-ROW('Teacher Calendar'!$D$43)+1),3)),"")} | B22: {=IFERROR(INDEX('Teacher Calendar'!$E$43:$E$52,SMALL(IF(('Teacher Calendar'!$E$43:$E$52<>"")*('Teacher Calendar'!$E$43:$E$52<>0),ROW('Teacher Calendar'!$E$43:$E$52)-ROW('Teacher Calendar'!$E$43)+1),3)),"")} -> Demo | C22: {=IFERROR(INDEX('Teacher Calendar'!$F$43:$F$52,SMALL(IF(('Teacher Calendar'!$F$43:$F$52<>"")*('Teacher Calendar'!$F$43:$F$52<>0),ROW('Teacher Calendar'!$F$43:$F$52)-ROW('Teacher Calendar'!$F$43)+1),3)),"")} -> Demo | D22: {=IFERROR(INDEX('Teacher Calendar'!$G$43:$G$52,SMALL(IF(('Teacher Calendar'!$G$43:$G$52<>"")*('Teacher Calendar'!$G$43:$G$52<>0),ROW('Teacher Calendar'!$G$43:$G$52)-ROW('Teacher Calendar'!$G$43)+1),3)),"")} -> Demo | E22: {=IFERROR(INDEX('Teacher Calendar'!$H$43:$H$52,SMALL(IF(('Teacher Calendar'!$H$43:$H$52<>"")*('Teacher Calendar'!$H$43:$H$52<>0),ROW('Teacher Calendar'!$H$43:$H$52)-ROW('Teacher Calendar'!$H$43)+1),3)),"")} -> Demo
A23: {=IFERROR(INDEX('Teacher Calendar'!$D$43:$D$52,SMALL(IF(('Teacher Calendar'!$D$43:$D$52<>"")*('Teacher Calendar'!$D$43:$D$52<>0),ROW('Teacher Calendar'!$D$43:$D$52)-ROW('Teacher Calendar'!$D$43)+1),4)),"")} | B23: {=IFERROR(INDEX('Teacher Calendar'!$E$43:$E$52,SMALL(IF(('Teacher Calendar'!$E$43:$E$52<>"")*('Teacher Calendar'!$E$43:$E$52<>0),ROW('Teacher Calendar'!$E$43:$E$52)-ROW('Teacher Calendar'!$E$43)+1),4)),"")} -> Notes | C23: {=IFERROR(INDEX('Teacher Calendar'!$F$43:$F$52,SMALL(IF(('Teacher Calendar'!$F$43:$F$52<>"")*('Teacher Calendar'!$F$43:$F$52<>0),ROW('Teacher Calendar'!$F$43:$F$52)-ROW('Teacher Calendar'!$F$43)+1),4)),"")} -> Notes | D23: {=IFERROR(INDEX('Teacher Calendar'!$G$43:$G$52,SMALL(IF(('Teacher Calendar'!$G$43:$G$52<>"")*('Teacher Calendar'!$G$43:$G$52<>0),ROW('Teacher Calendar'!$G$43:$G$52)-ROW('Teacher Calendar'!$G$43)+1),4)),"")} -> Notes | E23: {=IFERROR(INDEX('Teacher Calendar'!$H$43:$H$52,SMALL(IF(('Teacher Calendar'!$H$43:$H$52<>"")*('Teacher Calendar'!$H$43:$H$52<>0),ROW('Teacher Calendar'!$H$43:$H$52)-ROW('Teacher Calendar'!$H$43)+1),4)),"")} -> Notes
A24: {=IFERROR(INDEX('Teacher Calendar'!$D$43:$D$52,SMALL(IF(('Teacher Calendar'!$D$43:$D$52<>"")*('Teacher Calendar'!$D$43:$D$52<>0),ROW('Teacher Calendar'!$D$43:$D$52)-ROW('Teacher Calendar'!$D$43)+1),5)),"")} | B24: {=IFERROR(INDEX('Teacher Calendar'!$E$43:$E$52,SMALL(IF(('Teacher Calendar'!$E$43:$E$52<>"")*('Teacher Calendar'!$E$43:$E$52<>0),ROW('Teacher Calendar'!$E$43:$E$52)-ROW('Teacher Calendar'!$E$43)+1),5)),"")} -> Investigation | C24: {=IFERROR(INDEX('Teacher Calendar'!$F$43:$F$52,SMALL(IF(('Teacher Calendar'!$F$43:$F$52<>"")*('Teacher Calendar'!$F$43:$F$52<>0),ROW('Teacher Calendar'!$F$43:$F$52)-ROW('Teacher Calendar'!$F$43)+1),5)),"")} -> Investigation | D24: {=IFERROR(INDEX('Teacher Calendar'!$G$43:$G$52,SMALL(IF(('Teacher Calendar'!$G$43:$G$52<>"")*('Teacher Calendar'!$G$43:$G$52<>0),ROW('Teacher Calendar'!$G$43:$G$52)-ROW('Teacher Calendar'!$G$43)+1),5)),"")} -> Investigation | E24: {=IFERROR(INDEX('Teacher Calendar'!$H$43:$H$52,SMALL(IF(('Teacher Calendar'!$H$43:$H$52<>"")*('Teacher Calendar'!$H$43:$H$52<>0),ROW('Teacher Calendar'!$H$43:$H$52)-ROW('Teacher Calendar'!$H$43)+1),5)),"")} -> Investigation
A25: {=IFERROR(INDEX('Teacher Calendar'!$D$43:$D$52,SMALL(IF(('Teacher Calendar'!$D$43:$D$52<>"")*('Teacher Calendar'!$D$43:$D$52<>0),ROW('Teacher Calendar'!$D$43:$D$52)-ROW('Teacher Calendar'!$D$43)+1),6)),"")} | B25: {=IFERROR(INDEX('Teacher Calendar'!$E$43:$E$52,SMALL(IF(('Teacher Calendar'!$E$43:$E$52<>"")*('Teacher Calendar'!$E$43:$E$52<>0),ROW('Teacher Calendar'!$E$43:$E$52)-ROW('Teacher Calendar'!$E$43)+1),6)),"")} -> Activity | C25: {=IFERROR(INDEX('Teacher Calendar'!$F$43:$F$52,SMALL(IF(('Teacher Calendar'!$F$43:$F$52<>"")*('Teacher Calendar'!$F$43:$F$52<>0),ROW('Teacher Calendar'!$F$43:$F$52)-ROW('Teacher Calendar'!$F$43)+1),6)),"")} -> Activity | D25: {=IFERROR(INDEX('Teacher Calendar'!$G$43:$G$52,SMALL(IF(('Teacher Calendar'!$G$43:$G$52<>"")*('Teacher Calendar'!$G$43:$G$52<>0),ROW('Teacher Calendar'!$G$43:$G$52)-ROW('Teacher Calendar'!$G$43)+1),6)),"")} -> Activity | E25: {=IFERROR(INDEX('Teacher Calendar'!$H$43:$H$52,SMALL(IF(('Teacher Calendar'!$H$43:$H$52<>"")*('Teacher Calendar'!$H$43:$H$52<>0),ROW('Teacher Calendar'!$H$43:$H$52)-ROW('Teacher Calendar'!$H$43)+1),6)),"")} -> Activity
A26: {=IFERROR(INDEX('Teacher Calendar'!$D$43:$D$52,SMALL(IF(('Teacher Calendar'!$D$43:$D$52<>"")*('Teacher Calendar'!$D$43:$D$52<>0),ROW('Teacher Calendar'!$D$43:$D$52)-ROW('Teacher Calendar'!$D$43)+1),7)),"")} | B26: {=IFERROR(INDEX('Teacher Calendar'!$E$43:$E$52,SMALL(IF(('Teacher Calendar'!$E$43:$E$52<>"")*('Teacher Calendar'!$E$43:$E$52<>0),ROW('Teacher Calendar'!$E$43:$E$52)-ROW('Teacher Calendar'!$E$43)+1),7)),"")} -> Practice Set | C26: {=IFERROR(INDEX('Teacher Calendar'!$F$43:$F$52,SMALL(IF(('Teacher Calendar'!$F$43:$F$52<>"")*('Teacher Calendar'!$F$43:$F$52<>0),ROW('Teacher Calendar'!$F$43:$F$52)-ROW('Teacher Calendar'!$F$43)+1),7)),"")} -> Practice Set | D26: {=IFERROR(INDEX('Teacher Calendar'!$G$43:$G$52,SMALL(IF(('Teacher Calendar'!$G$43:$G$52<>"")*('Teacher Calendar'!$G$43:$G$52<>0),ROW('Teacher Calendar'!$G$43:$G$52)-ROW('Teacher Calendar'!$G$43)+1),7)),"")} -> Practice Set | E26: {=IFERROR(INDEX('Teacher Calendar'!$H$43:$H$52,SMALL(IF(('Teacher Calendar'!$H$43:$H$52<>"")*('Teacher Calendar'!$H$43:$H$52<>0),ROW('Teacher Calendar'!$H$43:$H$52)-ROW('Teacher Calendar'!$H$43)+1),7)),"")} -> Practice Set
A27: ='Teacher Calendar'!D69 -> 46279 | B27: ='Teacher Calendar'!E69 -> 46280 | C27: ='Teacher Calendar'!F69 -> 46281 | D27: ='Teacher Calendar'!G69 -> 46282 | E27: ='Teacher Calendar'!H69 -> 46283
A28: {=IFERROR(INDEX('Teacher Calendar'!$D$70:$D$79,SMALL(IF(('Teacher Calendar'!$D$70:$D$79<>"")*('Teacher Calendar'!$D$70:$D$79<>0),ROW('Teacher Calendar'!$D$70:$D$79)-ROW('Teacher Calendar'!$D$70)+1),1)),"")} -> 1.2: Forces & N1L | B28: {=IFERROR(INDEX('Teacher Calendar'!$E$70:$E$79,SMALL(IF(('Teacher Calendar'!$E$70:$E$79<>"")*('Teacher Calendar'!$E$70:$E$79<>0),ROW('Teacher Calendar'!$E$70:$E$79)-ROW('Teacher Calendar'!$E$70)+1),1)),"")} -> 1.2: Forces & N1L | C28: {=IFERROR(INDEX('Teacher Calendar'!$F$70:$F$79,SMALL(IF(('Teacher Calendar'!$F$70:$F$79<>"")*('Teacher Calendar'!$F$70:$F$79<>0),ROW('Teacher Calendar'!$F$70:$F$79)-ROW('Teacher Calendar'!$F$70)+1),1)),"")} -> 1.3: Net Force & Vec | D28: {=IFERROR(INDEX('Teacher Calendar'!$G$70:$G$79,SMALL(IF(('Teacher Calendar'!$G$70:$G$79<>"")*('Teacher Calendar'!$G$70:$G$79<>0),ROW('Teacher Calendar'!$G$70:$G$79)-ROW('Teacher Calendar'!$G$70)+1),1)),"")} -> 1.3: Net Force & Vec | E28: {=IFERROR(INDEX('Teacher Calendar'!$H$70:$H$79,SMALL(IF(('Teacher Calendar'!$H$70:$H$79<>"")*('Teacher Calendar'!$H$70:$H$79<>0),ROW('Teacher Calendar'!$H$70:$H$79)-ROW('Teacher Calendar'!$H$70)+1),1)),"")} -> 1.3: Net Force & Vec
A29: {=IFERROR(INDEX('Teacher Calendar'!$D$70:$D$79,SMALL(IF(('Teacher Calendar'!$D$70:$D$79<>"")*('Teacher Calendar'!$D$70:$D$79<>0),ROW('Teacher Calendar'!$D$70:$D$79)-ROW('Teacher Calendar'!$D$70)+1),2)),"")} -> Warm Up | B29: {=IFERROR(INDEX('Teacher Calendar'!$E$70:$E$79,SMALL(IF(('Teacher Calendar'!$E$70:$E$79<>"")*('Teacher Calendar'!$E$70:$E$79<>0),ROW('Teacher Calendar'!$E$70:$E$79)-ROW('Teacher Calendar'!$E$70)+1),2)),"")} -> Warm Up | C29: {=IFERROR(INDEX('Teacher Calendar'!$F$70:$F$79,SMALL(IF(('Teacher Calendar'!$F$70:$F$79<>"")*('Teacher Calendar'!$F$70:$F$79<>0),ROW('Teacher Calendar'!$F$70:$F$79)-ROW('Teacher Calendar'!$F$70)+1),2)),"")} -> Warm Up | D29: {=IFERROR(INDEX('Teacher Calendar'!$G$70:$G$79,SMALL(IF(('Teacher Calendar'!$G$70:$G$79<>"")*('Teacher Calendar'!$G$70:$G$79<>0),ROW('Teacher Calendar'!$G$70:$G$79)-ROW('Teacher Calendar'!$G$70)+1),2)),"")} -> Warm Up | E29: {=IFERROR(INDEX('Teacher Calendar'!$H$70:$H$79,SMALL(IF(('Teacher Calendar'!$H$70:$H$79<>"")*('Teacher Calendar'!$H$70:$H$79<>0),ROW('Teacher Calendar'!$H$70:$H$79)-ROW('Teacher Calendar'!$H$70)+1),2)),"")} -> Warm Up
A30: {=IFERROR(INDEX('Teacher Calendar'!$D$70:$D$79,SMALL(IF(('Teacher Calendar'!$D$70:$D$79<>"")*('Teacher Calendar'!$D$70:$D$79<>0),ROW('Teacher Calendar'!$D$70:$D$79)-ROW('Teacher Calendar'!$D$70)+1),3)),"")} -> Demo | B30: {=IFERROR(INDEX('Teacher Calendar'!$E$70:$E$79,SMALL(IF(('Teacher Calendar'!$E$70:$E$79<>"")*('Teacher Calendar'!$E$70:$E$79<>0),ROW('Teacher Calendar'!$E$70:$E$79)-ROW('Teacher Calendar'!$E$70)+1),3)),"")} -> Demo | C30: {=IFERROR(INDEX('Teacher Calendar'!$F$70:$F$79,SMALL(IF(('Teacher Calendar'!$F$70:$F$79<>"")*('Teacher Calendar'!$F$70:$F$79<>0),ROW('Teacher Calendar'!$F$70:$F$79)-ROW('Teacher Calendar'!$F$70)+1),3)),"")} -> Demo | D30: {=IFERROR(INDEX('Teacher Calendar'!$G$70:$G$79,SMALL(IF(('Teacher Calendar'!$G$70:$G$79<>"")*('Teacher Calendar'!$G$70:$G$79<>0),ROW('Teacher Calendar'!$G$70:$G$79)-ROW('Teacher Calendar'!$G$70)+1),3)),"")} -> Demo | E30: {=IFERROR(INDEX('Teacher Calendar'!$H$70:$H$79,SMALL(IF(('Teacher Calendar'!$H$70:$H$79<>"")*('Teacher Calendar'!$H$70:$H$79<>0),ROW('Teacher Calendar'!$H$70:$H$79)-ROW('Teacher Calendar'!$H$70)+1),3)),"")} -> Demo
A31: {=IFERROR(INDEX('Teacher Calendar'!$D$70:$D$79,SMALL(IF(('Teacher Calendar'!$D$70:$D$79<>"")*('Teacher Calendar'!$D$70:$D$79<>0),ROW('Teacher Calendar'!$D$70:$D$79)-ROW('Teacher Calendar'!$D$70)+1),4)),"")} -> Notes | B31: {=IFERROR(INDEX('Teacher Calendar'!$E$70:$E$79,SMALL(IF(('Teacher Calendar'!$E$70:$E$79<>"")*('Teacher Calendar'!$E$70:$E$79<>0),ROW('Teacher Calendar'!$E$70:$E$79)-ROW('Teacher Calendar'!$E$70)+1),4)),"")} -> Notes | C31: {=IFERROR(INDEX('Teacher Calendar'!$F$70:$F$79,SMALL(IF(('Teacher Calendar'!$F$70:$F$79<>"")*('Teacher Calendar'!$F$70:$F$79<>0),ROW('Teacher Calendar'!$F$70:$F$79)-ROW('Teacher Calendar'!$F$70)+1),4)),"")} -> Notes | D31: {=IFERROR(INDEX('Teacher Calendar'!$G$70:$G$79,SMALL(IF(('Teacher Calendar'!$G$70:$G$79<>"")*('Teacher Calendar'!$G$70:$G$79<>0),ROW('Teacher Calendar'!$G$70:$G$79)-ROW('Teacher Calendar'!$G$70)+1),4)),"")} -> Notes | E31: {=IFERROR(INDEX('Teacher Calendar'!$H$70:$H$79,SMALL(IF(('Teacher Calendar'!$H$70:$H$79<>"")*('Teacher Calendar'!$H$70:$H$79<>0),ROW('Teacher Calendar'!$H$70:$H$79)-ROW('Teacher Calendar'!$H$70)+1),4)),"")} -> Notes
A32: {=IFERROR(INDEX('Teacher Calendar'!$D$70:$D$79,SMALL(IF(('Teacher Calendar'!$D$70:$D$79<>"")*('Teacher Calendar'!$D$70:$D$79<>0),ROW('Teacher Calendar'!$D$70:$D$79)-ROW('Teacher Calendar'!$D$70)+1),5)),"")} -> Investigation | B32: {=IFERROR(INDEX('Teacher Calendar'!$E$70:$E$79,SMALL(IF(('Teacher Calendar'!$E$70:$E$79<>"")*('Teacher Calendar'!$E$70:$E$79<>0),ROW('Teacher Calendar'!$E$70:$E$79)-ROW('Teacher Calendar'!$E$70)+1),5)),"")} -> Investigation | C32: {=IFERROR(INDEX('Teacher Calendar'!$F$70:$F$79,SMALL(IF(('Teacher Calendar'!$F$70:$F$79<>"")*('Teacher Calendar'!$F$70:$F$79<>0),ROW('Teacher Calendar'!$F$70:$F$79)-ROW('Teacher Calendar'!$F$70)+1),5)),"")} -> Investigation | D32: {=IFERROR(INDEX('Teacher Calendar'!$G$70:$G$79,SMALL(IF(('Teacher Calendar'!$G$70:$G$79<>"")*('Teacher Calendar'!$G$70:$G$79<>0),ROW('Teacher Calendar'!$G$70:$G$79)-ROW('Teacher Calendar'!$G$70)+1),5)),"")} -> Investigation | E32: {=IFERROR(INDEX('Teacher Calendar'!$H$70:$H$79,SMALL(IF(('Teacher Calendar'!$H$70:$H$79<>"")*('Teacher Calendar'!$H$70:$H$79<>0),ROW('Teacher Calendar'!$H$70:$H$79)-ROW('Teacher Calendar'!$H$70)+1),5)),"")} -> Investigation
A33: {=IFERROR(INDEX('Teacher Calendar'!$D$70:$D$79,SMALL(IF(('Teacher Calendar'!$D$70:$D$79<>"")*('Teacher Calendar'!$D$70:$D$79<>0),ROW('Teacher Calendar'!$D$70:$D$79)-ROW('Teacher Calendar'!$D$70)+1),6)),"")} -> Activity | B33: {=IFERROR(INDEX('Teacher Calendar'!$E$70:$E$79,SMALL(IF(('Teacher Calendar'!$E$70:$E$79<>"")*('Teacher Calendar'!$E$70:$E$79<>0),ROW('Teacher Calendar'!$E$70:$E$79)-ROW('Teacher Calendar'!$E$70)+1),6)),"")} -> Activity | C33: {=IFERROR(INDEX('Teacher Calendar'!$F$70:$F$79,SMALL(IF(('Teacher Calendar'!$F$70:$F$79<>"")*('Teacher Calendar'!$F$70:$F$79<>0),ROW('Teacher Calendar'!$F$70:$F$79)-ROW('Teacher Calendar'!$F$70)+1),6)),"")} -> Activity | D33: {=IFERROR(INDEX('Teacher Calendar'!$G$70:$G$79,SMALL(IF(('Teacher Calendar'!$G$70:$G$79<>"")*('Teacher Calendar'!$G$70:$G$79<>0),ROW('Teacher Calendar'!$G$70:$G$79)-ROW('Teacher Calendar'!$G$70)+1),6)),"")} -> Activity | E33: {=IFERROR(INDEX('Teacher Calendar'!$H$70:$H$79,SMALL(IF(('Teacher Calendar'!$H$70:$H$79<>"")*('Teacher Calendar'!$H$70:$H$79<>0),ROW('Teacher Calendar'!$H$70:$H$79)-ROW('Teacher Calendar'!$H$70)+1),6)),"")} -> Activity
A34: {=IFERROR(INDEX('Teacher Calendar'!$D$70:$D$79,SMALL(IF(('Teacher Calendar'!$D$70:$D$79<>"")*('Teacher Calendar'!$D$70:$D$79<>0),ROW('Teacher Calendar'!$D$70:$D$79)-ROW('Teacher Calendar'!$D$70)+1),7)),"")} -> Practice Set | B34: {=IFERROR(INDEX('Teacher Calendar'!$E$70:$E$79,SMALL(IF(('Teacher Calendar'!$E$70:$E$79<>"")*('Teacher Calendar'!$E$70:$E$79<>0),ROW('Teacher Calendar'!$E$70:$E$79)-ROW('Teacher Calendar'!$E$70)+1),7)),"")} -> Practice Set | C34: {=IFERROR(INDEX('Teacher Calendar'!$F$70:$F$79,SMALL(IF(('Teacher Calendar'!$F$70:$F$79<>"")*('Teacher Calendar'!$F$70:$F$79<>0),ROW('Teacher Calendar'!$F$70:$F$79)-ROW('Teacher Calendar'!$F$70)+1),7)),"")} -> Practice Set | D34: {=IFERROR(INDEX('Teacher Calendar'!$G$70:$G$79,SMALL(IF(('Teacher Calendar'!$G$70:$G$79<>"")*('Teacher Calendar'!$G$70:$G$79<>0),ROW('Teacher Calendar'!$G$70:$G$79)-ROW('Teacher Calendar'!$G$70)+1),7)),"")} -> Practice Set | E34: {=IFERROR(INDEX('Teacher Calendar'!$H$70:$H$79,SMALL(IF(('Teacher Calendar'!$H$70:$H$79<>"")*('Teacher Calendar'!$H$70:$H$79<>0),ROW('Teacher Calendar'!$H$70:$H$79)-ROW('Teacher Calendar'!$H$70)+1),7)),"")} -> Practice Set
A35: ='Teacher Calendar'!D96 -> 46286 | B35: ='Teacher Calendar'!E96 -> 46287 | C35: ='Teacher Calendar'!F96 -> 46288 | D35: ='Teacher Calendar'!G96 -> 46289 | E35: ='Teacher Calendar'!H96 -> 46290
A36: {=IFERROR(INDEX('Teacher Calendar'!$D$97:$D$106,SMALL(IF(('Teacher Calendar'!$D$97:$D$106<>"")*('Teacher Calendar'!$D$97:$D$106<>0),ROW('Teacher Calendar'!$D$97:$D$106)-ROW('Teacher Calendar'!$D$97)+1),1)),"")} -> PD | B36: {=IFERROR(INDEX('Teacher Calendar'!$E$97:$E$106,SMALL(IF(('Teacher Calendar'!$E$97:$E$106<>"")*('Teacher Calendar'!$E$97:$E$106<>0),ROW('Teacher Calendar'!$E$97:$E$106)-ROW('Teacher Calendar'!$E$97)+1),1)),"")} -> 1.4: Equilibrium | C36: {=IFERROR(INDEX('Teacher Calendar'!$F$97:$F$106,SMALL(IF(('Teacher Calendar'!$F$97:$F$106<>"")*('Teacher Calendar'!$F$97:$F$106<>0),ROW('Teacher Calendar'!$F$97:$F$106)-ROW('Teacher Calendar'!$F$97)+1),1)),"")} -> 1.4: Equilibrium | D36: {=IFERROR(INDEX('Teacher Calendar'!$G$97:$G$106,SMALL(IF(('Teacher Calendar'!$G$97:$G$106<>"")*('Teacher Calendar'!$G$97:$G$106<>0),ROW('Teacher Calendar'!$G$97:$G$106)-ROW('Teacher Calendar'!$G$97)+1),1)),"")} -> 1.4: Equilibrium | E36: {=IFERROR(INDEX('Teacher Calendar'!$H$97:$H$106,SMALL(IF(('Teacher Calendar'!$H$97:$H$106<>"")*('Teacher Calendar'!$H$97:$H$106<>0),ROW('Teacher Calendar'!$H$97:$H$106)-ROW('Teacher Calendar'!$H$97)+1),1)),"")} -> 1.5: Force Models
A37: {=IFERROR(INDEX('Teacher Calendar'!$D$97:$D$106,SMALL(IF(('Teacher Calendar'!$D$97:$D$106<>"")*('Teacher Calendar'!$D$97:$D$106<>0),ROW('Teacher Calendar'!$D$97:$D$106)-ROW('Teacher Calendar'!$D$97)+1),2)),"")} | B37: {=IFERROR(INDEX('Teacher Calendar'!$E$97:$E$106,SMALL(IF(('Teacher Calendar'!$E$97:$E$106<>"")*('Teacher Calendar'!$E$97:$E$106<>0),ROW('Teacher Calendar'!$E$97:$E$106)-ROW('Teacher Calendar'!$E$97)+1),2)),"")} -> Warm Up | C37: {=IFERROR(INDEX('Teacher Calendar'!$F$97:$F$106,SMALL(IF(('Teacher Calendar'!$F$97:$F$106<>"")*('Teacher Calendar'!$F$97:$F$106<>0),ROW('Teacher Calendar'!$F$97:$F$106)-ROW('Teacher Calendar'!$F$97)+1),2)),"")} -> Warm Up | D37: {=IFERROR(INDEX('Teacher Calendar'!$G$97:$G$106,SMALL(IF(('Teacher Calendar'!$G$97:$G$106<>"")*('Teacher Calendar'!$G$97:$G$106<>0),ROW('Teacher Calendar'!$G$97:$G$106)-ROW('Teacher Calendar'!$G$97)+1),2)),"")} -> Warm Up | E37: {=IFERROR(INDEX('Teacher Calendar'!$H$97:$H$106,SMALL(IF(('Teacher Calendar'!$H$97:$H$106<>"")*('Teacher Calendar'!$H$97:$H$106<>0),ROW('Teacher Calendar'!$H$97:$H$106)-ROW('Teacher Calendar'!$H$97)+1),2)),"")} -> Warm Up
A38: {=IFERROR(INDEX('Teacher Calendar'!$D$97:$D$106,SMALL(IF(('Teacher Calendar'!$D$97:$D$106<>"")*('Teacher Calendar'!$D$97:$D$106<>0),ROW('Teacher Calendar'!$D$97:$D$106)-ROW('Teacher Calendar'!$D$97)+1),3)),"")} | B38: {=IFERROR(INDEX('Teacher Calendar'!$E$97:$E$106,SMALL(IF(('Teacher Calendar'!$E$97:$E$106<>"")*('Teacher Calendar'!$E$97:$E$106<>0),ROW('Teacher Calendar'!$E$97:$E$106)-ROW('Teacher Calendar'!$E$97)+1),3)),"")} -> Demo | C38: {=IFERROR(INDEX('Teacher Calendar'!$F$97:$F$106,SMALL(IF(('Teacher Calendar'!$F$97:$F$106<>"")*('Teacher Calendar'!$F$97:$F$106<>0),ROW('Teacher Calendar'!$F$97:$F$106)-ROW('Teacher Calendar'!$F$97)+1),3)),"")} -> Demo | D38: {=IFERROR(INDEX('Teacher Calendar'!$G$97:$G$106,SMALL(IF(('Teacher Calendar'!$G$97:$G$106<>"")*('Teacher Calendar'!$G$97:$G$106<>0),ROW('Teacher Calendar'!$G$97:$G$106)-ROW('Teacher Calendar'!$G$97)+1),3)),"")} -> Demo | E38: {=IFERROR(INDEX('Teacher Calendar'!$H$97:$H$106,SMALL(IF(('Teacher Calendar'!$H$97:$H$106<>"")*('Teacher Calendar'!$H$97:$H$106<>0),ROW('Teacher Calendar'!$H$97:$H$106)-ROW('Teacher Calendar'!$H$97)+1),3)),"")} -> Demo
A39: {=IFERROR(INDEX('Teacher Calendar'!$D$97:$D$106,SMALL(IF(('Teacher Calendar'!$D$97:$D$106<>"")*('Teacher Calendar'!$D$97:$D$106<>0),ROW('Teacher Calendar'!$D$97:$D$106)-ROW('Teacher Calendar'!$D$97)+1),4)),"")} | B39: {=IFERROR(INDEX('Teacher Calendar'!$E$97:$E$106,SMALL(IF(('Teacher Calendar'!$E$97:$E$106<>"")*('Teacher Calendar'!$E$97:$E$106<>0),ROW('Teacher Calendar'!$E$97:$E$106)-ROW('Teacher Calendar'!$E$97)+1),4)),"")} -> Notes | C39: {=IFERROR(INDEX('Teacher Calendar'!$F$97:$F$106,SMALL(IF(('Teacher Calendar'!$F$97:$F$106<>"")*('Teacher Calendar'!$F$97:$F$106<>0),ROW('Teacher Calendar'!$F$97:$F$106)-ROW('Teacher Calendar'!$F$97)+1),4)),"")} -> Notes | D39: {=IFERROR(INDEX('Teacher Calendar'!$G$97:$G$106,SMALL(IF(('Teacher Calendar'!$G$97:$G$106<>"")*('Teacher Calendar'!$G$97:$G$106<>0),ROW('Teacher Calendar'!$G$97:$G$106)-ROW('Teacher Calendar'!$G$97)+1),4)),"")} -> Notes | E39: {=IFERROR(INDEX('Teacher Calendar'!$H$97:$H$106,SMALL(IF(('Teacher Calendar'!$H$97:$H$106<>"")*('Teacher Calendar'!$H$97:$H$106<>0),ROW('Teacher Calendar'!$H$97:$H$106)-ROW('Teacher Calendar'!$H$97)+1),4)),"")} -> Notes
A40: {=IFERROR(INDEX('Teacher Calendar'!$D$97:$D$106,SMALL(IF(('Teacher Calendar'!$D$97:$D$106<>"")*('Teacher Calendar'!$D$97:$D$106<>0),ROW('Teacher Calendar'!$D$97:$D$106)-ROW('Teacher Calendar'!$D$97)+1),5)),"")} | B40: {=IFERROR(INDEX('Teacher Calendar'!$E$97:$E$106,SMALL(IF(('Teacher Calendar'!$E$97:$E$106<>"")*('Teacher Calendar'!$E$97:$E$106<>0),ROW('Teacher Calendar'!$E$97:$E$106)-ROW('Teacher Calendar'!$E$97)+1),5)),"")} -> Investigation | C40: {=IFERROR(INDEX('Teacher Calendar'!$F$97:$F$106,SMALL(IF(('Teacher Calendar'!$F$97:$F$106<>"")*('Teacher Calendar'!$F$97:$F$106<>0),ROW('Teacher Calendar'!$F$97:$F$106)-ROW('Teacher Calendar'!$F$97)+1),5)),"")} -> Investigation | D40: {=IFERROR(INDEX('Teacher Calendar'!$G$97:$G$106,SMALL(IF(('Teacher Calendar'!$G$97:$G$106<>"")*('Teacher Calendar'!$G$97:$G$106<>0),ROW('Teacher Calendar'!$G$97:$G$106)-ROW('Teacher Calendar'!$G$97)+1),5)),"")} -> Investigation | E40: {=IFERROR(INDEX('Teacher Calendar'!$H$97:$H$106,SMALL(IF(('Teacher Calendar'!$H$97:$H$106<>"")*('Teacher Calendar'!$H$97:$H$106<>0),ROW('Teacher Calendar'!$H$97:$H$106)-ROW('Teacher Calendar'!$H$97)+1),5)),"")} -> Investigation
A41: {=IFERROR(INDEX('Teacher Calendar'!$D$97:$D$106,SMALL(IF(('Teacher Calendar'!$D$97:$D$106<>"")*('Teacher Calendar'!$D$97:$D$106<>0),ROW('Teacher Calendar'!$D$97:$D$106)-ROW('Teacher Calendar'!$D$97)+1),6)),"")} | B41: {=IFERROR(INDEX('Teacher Calendar'!$E$97:$E$106,SMALL(IF(('Teacher Calendar'!$E$97:$E$106<>"")*('Teacher Calendar'!$E$97:$E$106<>0),ROW('Teacher Calendar'!$E$97:$E$106)-ROW('Teacher Calendar'!$E$97)+1),6)),"")} -> Activity | C41: {=IFERROR(INDEX('Teacher Calendar'!$F$97:$F$106,SMALL(IF(('Teacher Calendar'!$F$97:$F$106<>"")*('Teacher Calendar'!$F$97:$F$106<>0),ROW('Teacher Calendar'!$F$97:$F$106)-ROW('Teacher Calendar'!$F$97)+1),6)),"")} -> Activity | D41: {=IFERROR(INDEX('Teacher Calendar'!$G$97:$G$106,SMALL(IF(('Teacher Calendar'!$G$97:$G$106<>"")*('Teacher Calendar'!$G$97:$G$106<>0),ROW('Teacher Calendar'!$G$97:$G$106)-ROW('Teacher Calendar'!$G$97)+1),6)),"")} -> Activity | E41: {=IFERROR(INDEX('Teacher Calendar'!$H$97:$H$106,SMALL(IF(('Teacher Calendar'!$H$97:$H$106<>"")*('Teacher Calendar'!$H$97:$H$106<>0),ROW('Teacher Calendar'!$H$97:$H$106)-ROW('Teacher Calendar'!$H$97)+1),6)),"")} -> Activity
...

Sheet Teacher Calendar
C1: WK | D1: Monday | E1: Tuesday | F1: Wednesday | G1: Thursday | H1: Friday
A2: =B2+1 -> 11 | B2: =$C$2*10 -> 10 | C2: 1 | D2: =vlookup($A2,$A$15:$H$391,4) -> 46265 | E2: =vlookup($A2,$A$15:$H$391, 5) -> 46266 | F2: =vlookup($A2,$A$15:$H$391,6) -> 46267 | G2: =vlookup($A2,$A$15:$H$391,7) -> 46268 | H2: =vlookup($A2,$A$15:$H$391,8) -> 46269
A3: =B3+2 -> 12 | B3: =$C$2*10 -> 10 | D3: =vlookup($A3,$A$15:$H$391,4) -> 0.1 Get Acquainted | E3: =vlookup($A3,$A$15:$H$391, 5) -> 0.1 Get Acquainted | F3: =vlookup($A3,$A$15:$H$391,6) -> 0.1 Get Acquainted | G3: =vlookup($A3,$A$15:$H$391,7) -> House Keeping | H3: =vlookup($A3,$A$15:$H$391,8)
A4: =B4+3 -> 13 | B4: =$C$2*10 -> 10 | D4: =vlookup($A4,$A$15:$H$391,4) -> Warm Up | E4: =vlookup($A4,$A$15:$H$391, 5) -> Warm Up | F4: =vlookup($A4,$A$15:$H$391,6) -> Warm Up | G4: =vlookup($A4,$A$15:$H$391,7) -> Warm Up | H4: =vlookup($A4,$A$15:$H$391,8) -> Labor Day
A5: =B5+4 -> 14 | B5: =$C$2*10 -> 10 | D5: =vlookup($A5,$A$15:$H$391,4) -> Notes | E5: =vlookup($A5,$A$15:$H$391, 5) -> Investigation | F5: =vlookup($A5,$A$15:$H$391,6) -> Investigation | G5: =vlookup($A5,$A$15:$H$391,7) -> Activity | H5: =vlookup($A5,$A$15:$H$391,8)
A6: =B6+5 -> 15 | B6: =$C$2*10 -> 10 | D6: =vlookup($A6,$A$15:$H$391,4) -> Practice Set | E6: =vlookup($A6,$A$15:$H$391, 5) -> Practice Set | F6: =vlookup($A6,$A$15:$H$391,6) -> Activity | G6: =vlookup($A6,$A$15:$H$391,7) -> Return Portfolio | H6: =vlookup($A6,$A$15:$H$391,8)
A7: =B7+6 -> 16 | B7: =$C$2*10 -> 10 | D7: =vlookup($A7,$A$15:$H$391,4) | E7: =vlookup($A7,$A$15:$H$391, 5) -> Extra Practice | F7: =vlookup($A7,$A$15:$H$391,6) -> Practice Set | G7: =vlookup($A7,$A$15:$H$391,7) -> Overview | H7: =vlookup($A7,$A$15:$H$391,8)
A8: =B8+7 -> 17 | B8: =$C$2*10 -> 10 | D8: =vlookup($A8,$A$15:$H$391,4) | E8: =vlookup($A8,$A$15:$H$391, 5) | F8: =vlookup($A8,$A$15:$H$391,6) -> Extra Practice | G8: =vlookup($A8,$A$15:$H$391,7) -> Survey | H8: =vlookup($A8,$A$15:$H$391,8)
A9: =B9+8 -> 18 | B9: =$C$2*10 -> 10 | D9: =vlookup($A9,$A$15:$H$391,4) | E9: =vlookup($A9,$A$15:$H$391, 5) | F9: =vlookup($A9,$A$15:$H$391,6) | G9: =vlookup($A9,$A$15:$H$391,7) | H9: =vlookup($A9,$A$15:$H$391,8)
C10: Scroll Down for Previous Weeks
D11: 1 | E11: =D11+1 -> 2 | F11: =E11+1 -> 3 | G11: =F11+1 -> 4 | I11: =D11 -> 1 | J11: =E11 -> 2 | K11: =F11 -> 3 | L11: =G11 -> 4 | M11: =H11
D12: Don't Change Weeks columns below. Hide these 3 rows at start of school.
D13: In order to update week Just change week number. Also don't edit week above. If you need to change lesson do it below.
D14: Enter Start Date Below
A15: =B15+1 -> 11 | B15: =$C$15*10 -> 10 | C15: 1 | D15: 46265 | E15: =D15+1 -> 46266 | F15: =E15+1 -> 46267 | G15: =F15+1 -> 46268 | H15: =G15+1 -> 46269 | I15: Change number above
A16: =B16+2 -> 12 | B16: =$C$15*10 -> 10 | D16: =if(isblank(I16),"",vlookup(I16,Pacing!$A$1:$Z$213,2)) -> 0.1 Get Acquainted | E16: =if(isblank(J16),"",vlookup(J16,Pacing!$A$1:$Z$213,2)) -> 0.1 Get Acquainted | F16: =if(isblank(K16),"",vlookup(K16,Pacing!$A$1:$Z$213,2)) -> 0.1 Get Acquainted | G16: =if(isblank(L16),"",vlookup(L16,Pacing!$A$1:$Z$213,2)) -> House Keeping | H16: =if(isblank(M16),"",vlookup(M16,Pacing!$A$1:$Z$213,2)) | I16: =I11 -> 1 | J16: =J11 -> 2 | K16: =K11 -> 3 | L16: =L11 -> 4 | M16: =M11
A17: =B17+3 -> 13 | B17: =$C$15*10 -> 10 | D17: =if(isblank(I17),"",vlookup(I17,Pacing!$A$1:$Z$213,3)) -> Warm Up | E17: =if(isblank(J17),"",vlookup(J17,Pacing!$A$1:$Z$213,3)) -> Warm Up | F17: =if(isblank(K17),"",vlookup(K17,Pacing!$A$1:$Z$213,3)) -> Warm Up | G17: =if(isblank(L17),"",vlookup(L17,Pacing!$A$1:$Z$213,3)) -> Warm Up | H17: Labor Day | I17: =I16 -> 1 | J17: =J16 -> 2 | K17: =K16 -> 3 | L17: =L16 -> 4 | M17: =M16
A18: =B18+4 -> 14 | B18: =$C$15*10 -> 10 | D18: =if(isblank(I18),"",vlookup(I18,Pacing!$A$1:$Z$213,4)) -> Notes | E18: =if(isblank(J18),"",vlookup(J18,Pacing!$A$1:$Z$213,4)) -> Investigation | F18: =if(isblank(K18),"",vlookup(K18,Pacing!$A$1:$Z$213,4)) -> Investigation | G18: =if(isblank(L18),"",vlookup(L18,Pacing!$A$1:$Z$213,4)) -> Activity | H18: =if(isblank(M18),"",vlookup(M18,Pacing!$A$1:$Z$213,4)) | I18: =I17 -> 1 | J18: =J17 -> 2 | K18: =K17 -> 3 | L18: =L17 -> 4 | M18: =M17
A19: =B19+5 -> 15 | B19: =$C$15*10 -> 10 | D19: =if(isblank(I19),"",vlookup(I19,Pacing!$A$1:$Z$213,5)) -> Practice Set | E19: =if(isblank(J19),"",vlookup(J19,Pacing!$A$1:$Z$213,5)) -> Practice Set | F19: =if(isblank(K19),"",vlookup(K19,Pacing!$A$1:$Z$213,5)) -> Activity | G19: =if(isblank(L19),"",vlookup(L19,Pacing!$A$1:$Z$213,5)) -> Return Portfolio | H19: =if(isblank(M19),"",vlookup(M19,Pacing!$A$1:$Z$213,5)) | I19: =I18 -> 1 | J19: =J18 -> 2 | K19: =K18 -> 3 | L19: =L18 -> 4 | M19: =M18
A20: =B20+6 -> 16 | B20: =$C$15*10 -> 10 | D20: =if(isblank(I20),"",vlookup(I20,Pacing!$A$1:$Z$213,6)) | E20: =if(isblank(J20),"",vlookup(J20,Pacing!$A$1:$Z$213,6)) -> Extra Practice | F20: =if(isblank(K20),"",vlookup(K20,Pacing!$A$1:$Z$213,6)) -> Practice Set | G20: =if(isblank(L20),"",vlookup(L20,Pacing!$A$1:$Z$213,6)) -> Overview | H20: =if(isblank(M20),"",vlookup(M20,Pacing!$A$1:$Z$213,6)) | I20: =I19 -> 1 | J20: =J19 -> 2 | K20: =K19 -> 3 | L20: =L19 -> 4 | M20: =M19
A21: =B21+7 -> 17 | B21: =$C$15*10 -> 10 | D21: =if(isblank(I21),"",vlookup(I21,Pacing!$A$1:$Z$213,7)) | E21: =if(isblank(J21),"",vlookup(J21,Pacing!$A$1:$Z$213,7)) | F21: =if(isblank(K21),"",vlookup(K21,Pacing!$A$1:$Z$213,7)) -> Extra Practice | G21: =if(isblank(L21),"",vlookup(L21,Pacing!$A$1:$Z$213,7)) -> Survey | H21: =if(isblank(M21),"",vlookup(M21,Pacing!$A$1:$Z$213,7)) | I21: =I20 -> 1 | J21: =J20 -> 2 | K21: =K20 -> 3 | L21: =L20 -> 4 | M21: =M20
A22: =B22+8 -> 18 | B22: =$C$15*10 -> 10 | D22: =if(isblank(I22),"",vlookup(I22,Pacing!$A$1:$Z$213,8)) | E22: =if(isblank(J22),"",vlookup(J22,Pacing!$A$1:$Z$213,8)) | F22: =if(isblank(K22),"",vlookup(K22,Pacing!$A$1:$Z$213,8)) | G22: =if(isblank(L22),"",vlookup(L22,Pacing!$A$1:$Z$213,8)) | H22: =if(isblank(M22),"",vlookup(M22,Pacing!$A$1:$Z$213,8)) | I22: =I21 -> 1 | J22: =J21 -> 2 | K22: =K21 -> 3 | L22: =L21 -> 4 | M22: =M21
D23: =if(isblank(I23),"",vlookup(I23,Pacing!$A$1:$Z$213,9)) | E23: =if(isblank(J23),"",vlookup(J23,Pacing!$A$1:$Z$213,9)) | F23: =if(isblank(K23),"",vlookup(K23,Pacing!$A$1:$Z$213,9)) | G23: =if(isblank(L23),"",vlookup(L23,Pacing!$A$1:$Z$213,9)) | H23: =if(isblank(M23),"",vlookup(M23,Pacing!$A$1:$Z$213,9)) | I23: =I22 -> 1 | J23: =J22 -> 2 | K23: =K22 -> 3 | L23: =L22 -> 4 | M23: =M22
D24: =if(isblank(I24),"",vlookup(I24,Pacing!$A$1:$Z$213,10)) | E24: =if(isblank(J24),"",vlookup(J24,Pacing!$A$1:$Z$213,10)) | F24: =if(isblank(K24),"",vlookup(K24,Pacing!$A$1:$Z$213,10)) | G24: =if(isblank(L24),"",vlookup(L24,Pacing!$A$1:$Z$213,10)) | H24: =if(isblank(M24),"",vlookup(M24,Pacing!$A$1:$Z$213,10)) | I24: =I23 -> 1 | J24: =J23 -> 2 | K24: =K23 -> 3 | L24: =L23 -> 4 | M24: =M23
D25: =if(isblank(I25),"",vlookup(I25,Pacing!$A$1:$Z$213,11)) | E25: =if(isblank(J25),"",vlookup(J25,Pacing!$A$1:$Z$213,11)) | F25: =if(isblank(K25),"",vlookup(K25,Pacing!$A$1:$Z$213,11)) | G25: =if(isblank(L25),"",vlookup(L25,Pacing!$A$1:$Z$213,11)) | H25: =if(isblank(M25),"",vlookup(M25,Pacing!$A$1:$Z$213,11)) | I25: =I24 -> 1 | J25: =J24 -> 2 | K25: =K24 -> 3 | L25: =L24 -> 4 | M25: =M24
D26: =if(isblank(I26),"",vlookup(I26,Pacing!$A$1:$Z$213,12)) | E26: =if(isblank(J26),"",vlookup(J26,Pacing!$A$1:$Z$213,12)) | F26: =if(isblank(K26),"",vlookup(K26,Pacing!$A$1:$Z$213,12)) | G26: =if(isblank(L26),"",vlookup(L26,Pacing!$A$1:$Z$213,12)) | H26: =if(isblank(M26),"",vlookup(M26,Pacing!$A$1:$Z$213,12)) | I26: =I25 -> 1 | J26: =J25 -> 2 | K26: =K25 -> 3 | L26: =L25 -> 4 | M26: =M25
D27: =if(isblank(I27),"",vlookup(I27,Pacing!$A$1:$Z$213,13)) | E27: =if(isblank(J27),"",vlookup(J27,Pacing!$A$1:$Z$213,13)) | F27: =if(isblank(K27),"",vlookup(K27,Pacing!$A$1:$Z$213,13)) | G27: =if(isblank(L27),"",vlookup(L27,Pacing!$A$1:$Z$213,13)) | H27: =if(isblank(M27),"",vlookup(M27,Pacing!$A$1:$Z$213,13)) | I27: =I26 -> 1 | J27: =J26 -> 2 | K27: =K26 -> 3 | L27: =L26 -> 4 | M27: =M26
D28: =if(isblank(I28),"",vlookup(I28,Pacing!$A$1:$Z$213,14)) -> Notes Teacher | E28: =if(isblank(J28),"",vlookup(J28,Pacing!$A$1:$Z$213,14)) -> Invest Teacher | F28: =if(isblank(K28),"",vlookup(K28,Pacing!$A$1:$Z$213,14)) -> Invest Teacher | G28: =if(isblank(L28),"",vlookup(L28,Pacing!$A$1:$Z$213,14)) | H28: =if(isblank(M28),"",vlookup(M28,Pacing!$A$1:$Z$213,14)) | I28: =I27 -> 1 | J28: =J27 -> 2 | K28: =K27 -> 3 | L28: =L27 -> 4 | M28: =M27
D29: =if(isblank(I29),"",vlookup(I29,Pacing!$A$1:$Z$213,15)) -> Exit Ticket | E29: =if(isblank(J29),"",vlookup(J29,Pacing!$A$1:$Z$213,15)) -> Exit Ticket | F29: =if(isblank(K29),"",vlookup(K29,Pacing!$A$1:$Z$213,15)) -> Exit Ticket | G29: =if(isblank(L29),"",vlookup(L29,Pacing!$A$1:$Z$213,15)) | H29: =if(isblank(M29),"",vlookup(M29,Pacing!$A$1:$Z$213,15)) | I29: =I28 -> 1 | J29: =J28 -> 2 | K29: =K28 -> 3 | L29: =L28 -> 4 | M29: =M28
D30: =if(isblank(I30),"",vlookup(I30,Pacing!$A$1:$Z$213,16)) -> Give Exit Ticket | E30: =if(isblank(J30),"",vlookup(J30,Pacing!$A$1:$Z$213,16)) -> all 3 days. | F30: =if(isblank(K30),"",vlookup(K30,Pacing!$A$1:$Z$213,16)) | G30: =if(isblank(L30),"",vlookup(L30,Pacing!$A$1:$Z$213,16)) | H30: =if(isblank(M30),"",vlookup(M30,Pacing!$A$1:$Z$213,16)) | I30: =I29 -> 1 | J30: =J29 -> 2 | K30: =K29 -> 3 | L30: =L29 -> 4 | M30: =M29
D31: =if(isblank(I31),"",vlookup(I31,Pacing!$A$1:$Z$213,17)) -> PT Teacher | E31: =if(isblank(J31),"",vlookup(J31,Pacing!$A$1:$Z$213,17)) -> PT Teacher | F31: =if(isblank(K31),"",vlookup(K31,Pacing!$A$1:$Z$213,17)) -> PT Teacher | G31: =if(isblank(L31),"",vlookup(L31,Pacing!$A$1:$Z$213,17)) | H31: =if(isblank(M31),"",vlookup(M31,Pacing!$A$1:$Z$213,17)) | I31: =I30 -> 1 | J31: =J30 -> 2 | K31: =K30 -> 3 | L31: =L30 -> 4 | M31: =M30
D32: =if(isblank(I32),"",vlookup(I32,Pacing!$A$1:$Z$213,18)) -> Assess Plan | E32: =if(isblank(J32),"",vlookup(J32,Pacing!$A$1:$Z$213,18)) -> Assess Plan | F32: =if(isblank(K32),"",vlookup(K32,Pacing!$A$1:$Z$213,18)) -> Assess Plan | G32: =if(isblank(L32),"",vlookup(L32,Pacing!$A$1:$Z$213,18)) | H32: =if(isblank(M32),"",vlookup(M32,Pacing!$A$1:$Z$213,18)) | I32: =I31 -> 1 | J32: =J31 -> 2 | K32: =K31 -> 3 | L32: =L31 -> 4 | M32: =M31
D33: =if(isblank(I33),"",vlookup(I33,Pacing!$A$1:$Z$213,19)) -> Perform Task | E33: =if(isblank(J33),"",vlookup(J33,Pacing!$A$1:$Z$213,19)) -> Perform Task | F33: =if(isblank(K33),"",vlookup(K33,Pacing!$A$1:$Z$213,19)) -> Perform Task | G33: =if(isblank(L33),"",vlookup(L33,Pacing!$A$1:$Z$213,19)) | H33: =if(isblank(M33),"",vlookup(M33,Pacing!$A$1:$Z$213,19)) | I33: =I32 -> 1 | J33: =J32 -> 2 | K33: =K32 -> 3 | L33: =L32 -> 4 | M33: =M32
D34: =if(isblank(I34),"",vlookup(I34,Pacing!$A$1:$Z$213,20)) -> Quick Check | E34: =if(isblank(J34),"",vlookup(J34,Pacing!$A$1:$Z$213,20)) -> Quick Check | F34: =if(isblank(K34),"",vlookup(K34,Pacing!$A$1:$Z$213,20)) -> Quick Check | G34: =if(isblank(L34),"",vlookup(L34,Pacing!$A$1:$Z$213,20)) | H34: =if(isblank(M34),"",vlookup(M34,Pacing!$A$1:$Z$213,20)) | I34: =I33 -> 1 | J34: =J33 -> 2 | K34: =K33 -> 3 | L34: =L33 -> 4 | M34: =M33
D35: =if(isblank(I35),"",vlookup(I35,Pacing!$A$1:$Z$213,21)) -> Exit Ticket | E35: =if(isblank(J35),"",vlookup(J35,Pacing!$A$1:$Z$213,21)) -> Exit Ticket | F35: =if(isblank(K35),"",vlookup(K35,Pacing!$A$1:$Z$213,21)) -> Exit Ticket | G35: =if(isblank(L35),"",vlookup(L35,Pacing!$A$1:$Z$213,21)) | H35: =if(isblank(M35),"",vlookup(M35,Pacing!$A$1:$Z$213,21)) | I35: =I34 -> 1 | J35: =J34 -> 2 | K35: =K34 -> 3 | L35: =L34 -> 4 | M35: =M34
D36: =if(isblank(I36),"",vlookup(I36,Pacing!$A$1:$Z$213,22)) -> Practice 2 | E36: =if(isblank(J36),"",vlookup(J36,Pacing!$A$1:$Z$213,22)) -> Practice 2 | F36: =if(isblank(K36),"",vlookup(K36,Pacing!$A$1:$Z$213,22)) -> Practice 2 | G36: =if(isblank(L36),"",vlookup(L36,Pacing!$A$1:$Z$213,22)) | H36: =if(isblank(M36),"",vlookup(M36,Pacing!$A$1:$Z$213,22)) | I36: =I35 -> 1 | J36: =J35 -> 2 | K36: =K35 -> 3 | L36: =L35 -> 4 | M36: =M35
D37: =if(isblank(I37),"",vlookup(I37,Pacing!$A$1:$Z$213,23)) -> Practice 3 | E37: =if(isblank(J37),"",vlookup(J37,Pacing!$A$1:$Z$213,23)) -> Practice 3 | F37: =if(isblank(K37),"",vlookup(K37,Pacing!$A$1:$Z$213,23)) -> Practice 3 | G37: =if(isblank(L37),"",vlookup(L37,Pacing!$A$1:$Z$213,23)) | H37: =if(isblank(M37),"",vlookup(M37,Pacing!$A$1:$Z$213,23)) | I37: =I36 -> 1 | J37: =J36 -> 2 | K37: =K36 -> 3 | L37: =L36 -> 4 | M37: =M36
D38: =if(isblank(I38),"",vlookup(I38,Pacing!$A$1:$Z$213,24)) | E38: =if(isblank(J38),"",vlookup(J38,Pacing!$A$1:$Z$213,24)) | F38: =if(isblank(K38),"",vlookup(K38,Pacing!$A$1:$Z$213,24)) | G38: =if(isblank(L38),"",vlookup(L38,Pacing!$A$1:$Z$213,24)) | H38: =if(isblank(M38),"",vlookup(M38,Pacing!$A$1:$Z$213,24)) | I38: =I37 -> 1 | J38: =J37 -> 2 | K38: =K37 -> 3 | L38: =L37 -> 4 | M38: =M37
D39: =if(isblank(I39),"",vlookup(I39,Pacing!$A$1:$Z$213,25)) | E39: =if(isblank(J39),"",vlookup(J39,Pacing!$A$1:$Z$213,25)) | F39: =if(isblank(K39),"",vlookup(K39,Pacing!$A$1:$Z$213,25)) | G39: =if(isblank(L39),"",vlookup(L39,Pacing!$A$1:$Z$213,25)) | H39: =if(isblank(M39),"",vlookup(M39,Pacing!$A$1:$Z$213,25)) | I39: =I38 -> 1 | J39: =J38 -> 2 | K39: =K38 -> 3 | L39: =L38 -> 4 | M39: =M38
D40: =if(isblank(I40),"",vlookup(I40,Pacing!$A$1:$Z$213,26)) | E40: =if(isblank(J40),"",vlookup(J40,Pacing!$A$1:$Z$213,26)) | F40: =if(isblank(K40),"",vlookup(K40,Pacing!$A$1:$Z$213,26)) | G40: =if(isblank(L40),"",vlookup(L40,Pacing!$A$1:$Z$213,26)) | H40: =if(isblank(M40),"",vlookup(M40,Pacing!$A$1:$Z$213,26)) | I40: =I39 -> 1 | J40: =J39 -> 2 | K40: =K39 -> 3 | L40: =L39 -> 4 | M40: =M39
...

Sheet Pacing
A1: 1 | B1: 0.1 Get Acquainted | C1: Warm Up | D1: Notes | E1: Practice Set | N1: Notes Teacher | O1: Exit Ticket | P1: Give Exit Ticket | Q1: PT Teacher | R1: Assess Plan | S1: Perform Task | T1: Quick Check | U1: Exit Ticket | V1: Practice 2 | W1: Practice 3
A2: 2 | B2: 0.1 Get Acquainted | C2: Warm Up | D2: Investigation | E2: Practice Set | F2: Extra Practice | N2: Invest Teacher | O2: Exit Ticket | P2: all 3 days. | Q2: PT Teacher | R2: Assess Plan | S2: Perform Task | T2: Quick Check | U2: Exit Ticket | V2: Practice 2 | W2: Practice 3
A3: 3 | B3: 0.1 Get Acquainted | C3: Warm Up | D3: Investigation | E3: Activity | F3: Practice Set | G3: Extra Practice | N3: Invest Teacher | O3: Exit Ticket | Q3: PT Teacher | R3: Assess Plan | S3: Perform Task | T3: Quick Check | U3: Exit Ticket | V3: Practice 2 | W3: Practice 3
A4: 4 | B4: House Keeping | C4: Warm Up | D4: Activity | E4: Return Portfolio | F4: Overview | G4: Survey
A5: 5 | B5: 1.1: Think Physics | C5: Warm Up | D5: Demo | E5: Notes | F5: Investigation | G5: Activity | H5: Practice Set | I5: Extra Practice | J5: CYU | K5: Progress | L5: Review | N5: Notes Teacher | O5: Demo Teacher | P5: Invest Teacher | Q5: PT Teacher | R5: Assess Plan | S5: Perform Task | T5: Quick Check | U5: Exit Ticket | V5: Practice 2 | W5: Practice 3 | X5: Sum Assess | Y5: Bank
A6: 6 | B6: 1.1: Think Physics | C6: Warm Up | D6: Demo | E6: Notes | F6: Investigation | G6: Activity | H6: Practice Set | I6: Extra Practice | J6: CYU | K6: Progress | L6: Review | N6: Notes Teacher | O6: Demo Teacher | P6: Invest Teacher | Q6: PT Teacher | R6: Assess Plan | S6: Perform Task | T6: Quick Check | U6: Exit Ticket | V6: Practice 2 | W6: Practice 3 | X6: Sum Assess | Y6: Bank
A7: 7 | B7: 1.1: Think Physics | C7: Warm Up | D7: Demo | E7: Notes | F7: Investigation | G7: Activity | H7: Practice Set | I7: Extra Practice | J7: CYU | K7: Progress | L7: Review | N7: Notes Teacher | O7: Demo Teacher | P7: Invest Teacher | Q7: PT Teacher | R7: Assess Plan | S7: Perform Task | T7: Quick Check | U7: Exit Ticket | V7: Practice 2 | W7: Practice 3 | X7: Sum Assess | Y7: Bank
A8: 8 | B8: 1.2: Forces & N1L | C8: Warm Up | D8: Demo | E8: Notes | F8: Investigation | G8: Activity | H8: Practice Set | I8: Extra Practice | J8: CYU | K8: Progress | L8: Review | N8: Notes Teacher | O8: Demo Teacher | P8: Invest Teacher | Q8: PT Teacher | R8: Assess Plan | S8: Perform Task | T8: Quick Check | U8: Exit Ticket | V8: Practice 2 | W8: Practice 3 | X8: Sum Assess | Y8: Bank
A9: 9 | B9: 1.2: Forces & N1L | C9: Warm Up | D9: Demo | E9: Notes | F9: Investigation | G9: Activity | H9: Practice Set | I9: Extra Practice | J9: CYU | K9: Progress | L9: Review | N9: Notes Teacher | O9: Demo Teacher | P9: Invest Teacher | Q9: PT Teacher | R9: Assess Plan | S9: Perform Task | T9: Quick Check | U9: Exit Ticket | V9: Practice 2 | W9: Practice 3 | X9: Sum Assess | Y9: Bank
A10: 10 | B10: 1.2: Forces & N1L | C10: Warm Up | D10: Demo | E10: Notes | F10: Investigation | G10: Activity | H10: Practice Set | I10: Extra Practice | J10: CYU | K10: Progress | L10: Review | N10: Notes Teacher | O10: Demo Teacher | P10: Invest Teacher | Q10: PT Teacher | R10: Assess Plan | S10: Perform Task | T10: Quick Check | U10: Exit Ticket | V10: Practice 2 | W10: Practice 3 | X10: Sum Assess | Y10: Bank
A11: 11 | B11: 1.3: Net Force & Vec | C11: Warm Up | D11: Demo | E11: Notes | F11: Investigation | G11: Activity | H11: Practice Set | I11: Extra Practice | J11: CYU | K11: Progress | L11: Review | N11: Notes Teacher | O11: Demo Teacher | P11: Invest Teacher | Q11: PT Teacher | R11: Assess Plan | S11: Perform Task | T11: Quick Check | U11: Exit Ticket | V11: Practice 2 | W11: Practice 3 | X11: Sum Assess | Y11: Bank
A12: 12 | B12: 1.3: Net Force & Vec | C12: Warm Up | D12: Demo | E12: Notes | F12: Investigation | G12: Activity | H12: Practice Set | I12: Extra Practice | J12: CYU | K12: Progress | L12: Review | N12: Notes Teacher | O12: Demo Teacher | P12: Invest Teacher | Q12: PT Teacher | R12: Assess Plan | S12: Perform Task | T12: Quick Check | U12: Exit Ticket | V12: Practice 2 | W12: Practice 3 | X12: Sum Assess | Y12: Bank
A13: 13 | B13: 1.3: Net Force & Vec | C13: Warm Up | D13: Demo | E13: Notes | F13: Investigation | G13: Activity | H13: Practice Set | I13: Extra Practice | J13: CYU | K13: Progress | L13: Review | N13: Notes Teacher | O13: Demo Teacher | P13: Invest Teacher | Q13: PT Teacher | R13: Assess Plan | S13: Perform Task | T13: Quick Check | U13: Exit Ticket | V13: Practice 2 | W13: Practice 3 | X13: Sum Assess | Y13: Bank
A14: 14 | B14: 1.4: Equilibrium | C14: Warm Up | D14: Demo | E14: Notes | F14: Investigation | G14: Activity | H14: Practice Set | I14: Extra Practice | J14: CYU | K14: Progress | L14: Review | N14: Notes Teacher | O14: Demo Teacher | P14: Invest Teacher | Q14: PT Teacher | R14: Assess Plan | S14: Perform Task | T14: Quick Check | U14: Exit Ticket | V14: Practice 2 | W14: Practice 3 | X14: Sum Assess | Y14: Bank
A15: 15 | B15: 1.4: Equilibrium | C15: Warm Up | D15: Demo | E15: Notes | F15: Investigation | G15: Activity | H15: Practice Set | I15: Extra Practice | J15: CYU | K15: Progress | L15: Review | N15: Notes Teacher | O15: Demo Teacher | P15: Invest Teacher | Q15: PT Teacher | R15: Assess Plan | S15: Perform Task | T15: Quick Check | U15: Exit Ticket | V15: Practice 2 | W15: Practice 3 | X15: Sum Assess | Y15: Bank
A16: 16 | B16: 1.4: Equilibrium | C16: Warm Up | D16: Demo | E16: Notes | F16: Investigation | G16: Activity | H16: Practice Set | I16: Extra Practice | J16: CYU | K16: Progress | L16: Review | N16: Notes Teacher | O16: Demo Teacher | P16: Invest Teacher | Q16: PT Teacher | R16: Assess Plan | S16: Perform Task | T16: Quick Check | U16: Exit Ticket | V16: Practice 2 | W16: Practice 3 | X16: Sum Assess | Y16: Bank
... A19: 19 | B19: 1.5: Force Models | C19: Warm Up | D19: Demo | E19: Notes | F19: Investigation | G19: Activity | H19: Practice Set | I19: Extra Practice | J19: CYU | K19: Progress | L19: Review | N19: Notes Teacher | O19: Demo Teacher | P19: Invest Teacher | Q19: PT Teacher | R19: Assess Plan | S19: Perform Task | T19: Quick Check | U19: Exit Ticket | V19: Practice 2 | W19: Practice 3 | X19: Sum Assess | Y19: Bank
A20: 20 | B20: Unit 1 Sum Assess | N20: Sum Assess | O20: Bank | P20: Assess Plan
A21: 21 | B21: 2.1: Motion & Ref | C21: Warm Up | D21: Demo | E21: Notes | F21: Investigation | G21: Activity | H21: Practice Set | I21: Extra Practice | J21: CYU | K21: Progress | L21: Review | N21: Notes Teacher | O21: Demo Teacher | P21: Invest Teacher | Q21: PT Teacher | R21: Assess Plan | S21: Perform Task | T21: Quick Check | U21: Exit Ticket | V21: Practice 2 | W21: Practice 3 | X21: Sum Assess | Y21: Bank
A22: 22 | B22: 2.1: Motion & Ref | C22: Warm Up | D22: Demo | E22: Notes | F22: Investigation | G22: Activity | H22: Practice Set | I22: Extra Practice | J22: CYU | K22: Progress | L22: Review | N22: Notes Teacher | O22: Demo Teacher | P22: Invest Teacher | Q22: PT Teacher | R22: Assess Plan | S22: Perform Task | T22: Quick Check | U22: Exit Ticket | V22: Practice 2 | W22: Practice 3 | X22: Sum Assess | Y22: Bank
A23: 23 | B23: 2.1: Motion & Ref | C23: Warm Up | D23: Demo | E23: Notes | F23: Investigation | G23: Activity | H23: Practice Set | I23: Extra Practice | J23: CYU | K23: Progress | L23: Review | N23: Notes Teacher | O23: Demo Teacher | P23: Invest Teacher | Q23: PT Teacher | R23: Assess Plan | S23: Perform Task | T23: Quick Check | U23: Exit Ticket | V23: Practice 2 | W23: Practice 3 | X23: Sum Assess | Y23: Bank
A24: 24 | B24: 2.2: Speed & Vel | C24: Warm Up | D24: Demo | E24: Notes | F24: Investigation | G24: Activity | H24: Practice Set | I24: Extra Practice | J24: CYU | K24: Progress | L24: Review | N24: Notes Teacher | O24: Demo Teacher | P24: Invest Teacher | Q24: PT Teacher | R24: Assess Plan | S24: Perform Task | T24: Quick Check | U24: Exit Ticket | V24: Practice 2 | W24: Practice 3 | X24: Sum Assess | Y24: Bank
A25: 25 | B25: 2.2: Speed & Vel | C25: Warm Up | D25: Demo | E25: Notes | F25: Investigation | G25: Activity | H25: Practice Set | I25: Extra Practice | J25: CYU | K25: Progress | L25: Review | N25: Notes Teacher | O25: Demo Teacher | P25: Invest Teacher | Q25: PT Teacher | R25: Assess Plan | S25: Perform Task | T25: Quick Check | U25: Exit Ticket | V25: Practice 2 | W25: Practice 3 | X25: Sum Assess | Y25: Bank
A26: 26 | B26: 2.2: Speed & Vel | C26: Warm Up | D26: Demo | E26: Notes | F26: Investigation | G26: Activity | H26: Practice Set | I26: Extra Practice | J26: CYU | K26: Progress | L26: Review | N26: Notes Teacher | O26: Demo Teacher | P26: Invest Teacher | Q26: PT Teacher | R26: Assess Plan | S26: Perform Task | T26: Quick Check | U26: Exit Ticket | V26: Practice 2 | W26: Practice 3 | X26: Sum Assess | Y26: Bank
A27: 27 | B27: 2.3: Acceleration | C27: Warm Up | D27: Demo | E27: Notes | F27: Investigation | G27: Activity | H27: Practice Set | I27: Extra Practice | J27: CYU | K27: Progress | L27: Review | N27: Notes Teacher | O27: Demo Teacher | P27: Invest Teacher | Q27: PT Teacher | R27: Assess Plan | S27: Perform Task | T27: Quick Check | U27: Exit Ticket | V27: Practice 2 | W27: Practice 3 | X27: Sum Assess | Y27: Bank
A28: 28 | B28: 2.3: Acceleration | C28: Warm Up | D28: Demo | E28: Notes | F28: Investigation | G28: Activity | H28: Practice Set | I28: Extra Practice | J28: CYU | K28: Progress | L28: Review | N28: Notes Teacher | O28: Demo Teacher | P28: Invest Teacher | Q28: PT Teacher | R28: Assess Plan | S28: Perform Task | T28: Quick Check | U28: Exit Ticket | V28: Practice 2 | W28: Practice 3 | X28: Sum Assess | Y28: Bank
A29: 29 | B29: 2.3: Acceleration | C29: Warm Up | D29: Demo | E29: Notes | F29: Investigation | G29: Activity | H29: Practice Set | I29: Extra Practice | J29: CYU | K29: Progress | L29: Review | N29: Notes Teacher | O29: Demo Teacher | P29: Invest Teacher | Q29: PT Teacher | R29: Assess Plan | S29: Perform Task | T29: Quick Check | U29: Exit Ticket | V29: Practice 2 | W29: Practice 3 | X29: Sum Assess | Y29: Bank
A30: 30 | B30: 2.4: Free Fall | C30: Warm Up | D30: Demo | E30: Notes | F30: Investigation | G30: Activity | H30: Practice Set | I30: Extra Practice | J30: CYU | K30: Progress | L30: Review | N30: Notes Teacher | O30: Demo Teacher | P30: Invest Teacher | Q30: PT Teacher | R30: Assess Plan | S30: Perform Task | T30: Quick Check | U30: Exit Ticket | V30: Practice 2 | W30: Practice 3 | X30: Sum Assess | Y30: Bank
A31: 31 | B31: 2.4: Free Fall | C31: Warm Up | D31: Demo | E31: Notes | F31: Investigation | G31: Activity | H31: Practice Set | I31: Extra Practice | J31: CYU | K31: Progress | L31: Review | N31: Notes Teacher | O31: Demo Teacher | P31: Invest Teacher | Q31: PT Teacher | R31: Assess Plan | S31: Perform Task | T31: Quick Check | U31: Exit Ticket | V31: Practice 2 | W31: Practice 3 | X31: Sum Assess | Y31: Bank
A32: 32 | B32: 2.4: Free Fall | C32: Warm Up | D32: Demo | E32: Notes | F32: Investigation | G32: Activity | H32: Practice Set | I32: Extra Practice | J32: CYU | K32: Progress | L32: Review | N32: Notes Teacher | O32: Demo Teacher | P32: Invest Teacher | Q32: PT Teacher | R32: Assess Plan | S32: Perform Task | T32: Quick Check | U32: Exit Ticket | V32: Practice 2 | W32: Practice 3 | X32: Sum Assess | Y32: Bank
... A35: 35 | B35: 2.5: Vel Vectors | C35: Warm Up | D35: Demo | E35: Notes | F35: Investigation | G35: Activity | H35: Practice Set | I35: Extra Practice | J35: CYU | K35: Progress | L35: Review | N35: Notes Teacher | O35: Demo Teacher | P35: Invest Teacher | Q35: PT Teacher | R35: Assess Plan | S35: Perform Task | T35: Quick Check | U35: Exit Ticket | V35: Practice 2 | W35: Practice 3 | X35: Sum Assess | Y35: Bank
A36: 36 | B36: Unit 2 Sum Ass | N36: Sum Assess | O36: Bank | P36: Assess Plan
A37: 37 | B37: 3.1: Force & Accel | C37: Warm Up | D37: Demo | E37: Notes | F37: Investigation | G37: Activity | H37: Practice Set | I37: Extra Practice | J37: CYU | K37: Progress | L37: Review | N37: Notes Teacher | O37: Demo Teacher | P37: Invest Teacher | Q37: PT Teacher | R37: Assess Plan | S37: Perform Task | T37: Quick Check | U37: Exit Ticket | V37: Practice 2 | W37: Practice 3 | X37: Sum Assess | Y37: Bank
A38: 38 | B38: 3.1: Force & Accel | C38: Warm Up | D38: Demo | E38: Notes | F38: Investigation | G38: Activity | H38: Practice Set | I38: Extra Practice | J38: CYU | K38: Progress | L38: Review | N38: Notes Teacher | O38: Demo Teacher | P38: Invest Teacher | Q38: PT Teacher | R38: Assess Plan | S38: Perform Task | T38: Quick Check | U38: Exit Ticket | V38: Practice 2 | W38: Practice 3 | X38: Sum Assess | Y38: Bank
A39: 39 | B39: 3.1: Force & Accel | C39: Warm Up | D39: Demo | E39: Notes | F39: Investigation | G39: Activity | H39: Practice Set | I39: Extra Practice | J39: CYU | K39: Progress | L39: Review | N39: Notes Teacher | O39: Demo Teacher | P39: Invest Teacher | Q39: PT Teacher | R39: Assess Plan | S39: Perform Task | T39: Quick Check | U39: Exit Ticket | V39: Practice 2 | W39: Practice 3 | X39: Sum Assess | Y39: Bank
A40: 40 | B40: 3.2: Friction | C40: Warm Up | D40: Demo | E40: Notes | F40: Investigation | G40: Activity | H40: Practice Set | I40: Extra Practice | J40: CYU | K40: Progress | L40: Review | N40: Notes Teacher | O40: Demo Teacher | P40: Invest Teacher | Q40: PT Teacher | R40: Assess Plan | S40: Perform Task | T40: Quick Check | U40: Exit Ticket | V40: Practice 2 | W40: Practice 3 | X40: Sum Assess | Y40: Bank
